Workbook
Name Slicer_Order_Date: #N/A
Name Slicer_Total__USD: #N/A
Name Slicer_Customer_Name: #N/A
Name Slicer_Total__USD2: #N/A
Name TAX: 'cleaned dataset'!$H$8:$H$77

Sheet SuperMarket Sales
B2: Excel Sample Data
B4: Supermarket Sales Data
H6: Tax | I6: 0.1
B8: Order No | C8: Order Date | D8: Customer Name | E8: Ship Date | F8: Retail Price (USD) | G8: Order Quantity | H8: Tax (USD) | I8: Total (USD)
B9: 1001 | C9: 45292 | D9: John Smith | E9: 45294 | F9: 49.99 | G9: 2 | H9: =F9*G9*$I$6 -> 9.998 | I9: =F9*G9+H9 -> 109.978
B10: 1002 | C10: 45292 | D10: Jane Doe | E10: 45295 | F10: 29.99 | G10: 1 | H10: =F10*G10*$I$6 -> 2.999 | I10: =F10*G10+H10 -> 32.989
B11: 1003 | C11: 45293 | D11: Michael Johnson | E11: 45298 | F11: 99.99 | G11: 3 | H11: =F11*G11*$I$6 -> 29.997 | I11: =F11*G11+H11 -> 329.967
B12: 1004 | C12: 45293 | D12: Emily Brown | E12: 45294 | F12: 19.99 | G12: 4 | H12: =F12*G12*$I$6 -> 7.996 | I12: =F12*G12+H12 -> 87.956
B13: 1005 | C13: 45294 | D13: David Wilson | E13: 45299 | F13: 149.99 | G13: 1 | H13: =F13*G13*$I$6 -> 14.999 | I13: =F13*G13+H13 -> 164.989
B14: 1006 | C14: 45294 | D14: Lisa Taylor | E14: 45297 | F14: 79.99 | G14: 2 | H14: =F14*G14*$I$6 -> 15.998 | I14: =F14*G14+H14 -> 175.978
B15: 1007 | C15: 45295 | D15: Daniel Martinez | E15: 45297 | F15: 39.99 | G15: 3 | H15: =F15*G15*$I$6 -> 11.997 | I15: =F15*G15+H15 -> 131.967
B16: 1008 | C16: 45295 | D16: Sarah Anderson | E16: 45300 | F16: 69.99 | G16: 2 | H16: =F16*G16*$I$6 -> 13.998 | I16: =F16*G16+H16 -> 153.978
B17: 1009 | C17: 45296 | D17: Christopher Thomas | E17: 45297 | F17: 89.99 | G17: 1 | H17: =F17*G17*$I$6 -> 8.999 | I17: =F17*G17+H17 -> 98.989
B18: 1010 | C18: 45296 | D18: Kimberly Garcia | E18: 45299 | F18: 199.99 | G18: 1 | H18: =F18*G18*$I$6 -> 19.999 | I18: =F18*G18+H18 -> 219.989
B19: 1011 | C19: 45297 | D19: William Hernandez | E19: 45298 | F19: 29.99 | G19: 5 | H19: =F19*G19*$I$6 -> 14.995 | I19: =F19*G19+H19 -> 164.945
B20: 1012 | C20: 45297 | D20: Melissa Lopez | E20: 45299 | F20: 79.99 | G20: 2 | H20: =F20*G20*$I$6 -> 15.998 | I20: =F20*G20+H20 -> 175.978
... B78: 1070 | C78: 45326 | D78: Jennifer Hernandez | E78: 45329 | F78: 149.99 | G78: 1 | H78: =F78*G78*$I$6 -> 14.999 | I78: =F78*G78+H78 -> 164.989

Sheet cleaned dataset
B2: SUPERMARKET SALES ANAlYSIS
B5: Column1 | C5: Column2 | D5: Column3 | E5: Column4 | F5: Column5 | G5: Column6 | H5: Tax | I5: 10% | J5: Column7 | K5: Column9 | L5: Column10
K6: DAYS | L6: TEXT
B7: Order No | C7: Order Date | D7: Customer Name | E7: Ship Date | F7: Retail Price (USD) | G7: Order Quantity | H7: Tax (USD) | I7: Total (USD) | J7: Sales Before Tax | K7: Shipping Days | L7: Month
B8: 1001 | C8: 45292 | D8: John Smith | E8: 45299 | F8: 49.99 | G8: 2 | H8: =F8*G8*$I$5 -> 9.998 | I8: 109.98 | J8: =F8*G8 -> 99.98 | K8: =_xlfn.DAYS(E8,C8) -> 7 | L8: =TEXT(C8,"mmm") -> Jan
B9: 1002 | C9: 45323 | D9: Jane Doe | E9: 45326 | F9: 29.99 | G9: 1 | H9: =F9*G9*$I$5 -> 2.999 | I9: =F9*G9+H9 -> 32.989 | J9: =F9*G9 -> 29.99 | K9: =_xlfn.DAYS(E9,C9) -> 3 | L9: =TEXT(C9,"mmm") -> Feb
B10: 1003 | C10: 45353 | D10: Michael Johnson | E10: 45358 | F10: 99.99 | G10: 3 | H10: =F10*G10*$I$5 -> 29.997 | I10: =F10*G10+H10 -> 329.967 | J10: =F10*G10 -> 299.97 | K10: =_xlfn.DAYS(E10,C10) -> 5 | L10: =TEXT(C10,"mmm") -> Mar
B11: 1004 | C11: 45293 | D11: Emily Brown | E11: 45302 | F11: 19.99 | G11: 4 | H11: =F11*G11*$I$5 -> 7.996 | I11: =F11*G11+H11 -> 87.956 | J11: =F11*G11 -> 79.96 | K11: =_xlfn.DAYS(E11,C11) -> 9 | L11: =TEXT(C11,"mmm") -> Jan
B12: 1005 | C12: 45325 | D12: David Wilson | E12: 45330 | F12: 149.99 | G12: 1 | H12: =F12*G12*$I$5 -> 14.999 | I12: =F12*G12+H12 -> 164.989 | J12: =F12*G12 -> 149.99 | K12: =_xlfn.DAYS(E12,C12) -> 5 | L12: =TEXT(C12,"mmm") -> Feb
B13: 1006 | C13: 45354 | D13: Lisa Taylor | E13: 45357 | F13: 79.99 | G13: 2 | H13: =F13*G13*$I$5 -> 15.998 | I13: =F13*G13+H13 -> 175.978 | J13: =F13*G13 -> 159.98 | K13: =_xlfn.DAYS(E13,C13) -> 3 | L13: =TEXT(C13,"mmm") -> Mar
B14: 1007 | C14: 45295 | D14: Daniel Martinez | E14: 45299 | F14: 39.99 | G14: 3 | H14: =F14*G14*$I$5 -> 11.997 | I14: =F14*G14+H14 -> 131.967 | J14: =F14*G14 -> 119.97 | K14: =_xlfn.DAYS(E14,C14) -> 4 | L14: =TEXT(C14,"mmm") -> Jan
B15: 1008 | C15: 45386 | D15: Sarah Anderson | E15: 45391 | F15: 69.99 | G15: 2 | H15: =F15*G15*$I$5 -> 13.998 | I15: =F15*G15+H15 -> 153.978 | J15: =F15*G15 -> 139.98 | K15: =_xlfn.DAYS(E15,C15) -> 5 | L15: =TEXT(C15,"mmm") -> Apr
B16: 1009 | C16: 45417 | D16: Christopher Thomas | E16: 45421 | F16: 89.99 | G16: 1 | H16: =F16*G16*$I$5 -> 8.999 | I16: =F16*G16+H16 -> 98.989 | J16: =F16*G16 -> 89.99 | K16: =_xlfn.DAYS(E16,C16) -> 4 | L16: =TEXT(C16,"mmm") -> May
B17: 1010 | C17: 45296 | D17: Kimberly Garcia | E17: 45299 | F17: 199.99 | G17: 1 | H17: =F17*G17*$I$5 -> 19.999 | I17: =F17*G17+H17 -> 219.989 | J17: =F17*G17 -> 199.99 | K17: =_xlfn.DAYS(E17,C17) -> 3 | L17: =TEXT(C17,"mmm") -> Jan
B18: 1011 | C18: 45571 | D18: William Hernandez | E18: 45575 | F18: 29.99 | G18: 5 | H18: =F18*G18*$I$5 -> 14.995 | I18: =F18*G18+H18 -> 164.945 | J18: =F18*G18 -> 149.95 | K18: =_xlfn.DAYS(E18,C18) -> 4 | L18: =TEXT(C18,"mmm") -> Oct
B19: 1012 | C19: 45602 | D19: Melissa Lopez | E19: 45604 | F19: 79.99 | G19: 2 | H19: =F19*G19*$I$5 -> 15.998 | I19: =F19*G19+H19 -> 175.978 | J19: =F19*G19 -> 159.98 | K19: =_xlfn.DAYS(E19,C19) -> 2 | L19: =TEXT(C19,"mmm") -> Nov
B20: 1013 | C20: 45298 | D20: Richard Perez | E20: 45300 | F20: 49.99 | G20: 3 | H20: =F20*G20*$I$5 -> 14.997 | I20: =F20*G20+H20 -> 164.967 | J20: =F20*G20 -> 149.97 | K20: =_xlfn.DAYS(E20,C20) -> 2 | L20: =TEXT(C20,"mmm") -> Jan
... B77: 1070 | C77: 45326 | D77: Jennifer Hernandez | E77: 45329 | F77: 149.99 | G77: 1 | H77: =F77*G77*$I$5 -> 14.999 | I77: =F77*G77+H77 -> 164.989 | J77: =F77*G77 -> 149.99 | K77: =_xlfn.DAYS(E77,C77) -> 3 | L77: =TEXT(C77,"mmm") -> Feb
G78: =SUM(G8:G77) -> 168

Sheet logical functions
A1: LOGICAL FUNCTIONS
A4: IF | B4: 1)If Total > 150 High Value otherwise Normal | G4: NESTEDIF | H4: If Total < 100 its low, if >150 then it should be Medium or High
B5: =IF('cleaned dataset'!I8>150,"High Value","Normal") -> Normal | H5: =IF('cleaned dataset'!I8<100,"low",IF('cleaned dataset'!I8>=150,"Medium","High")) -> High
A8: SUMIF | B8: 2)Total Sales Made by John Smith
B9: =SUMIF('cleaned dataset'!D8:D77,"John Smith",'cleaned dataset'!I8:I77) -> 109.98
B11: 3)Find Total Sales Where Quantity is 3
B12: =SUMIF('cleaned dataset'!G8:G77,3,'cleaned dataset'!I8:I77) -> 2408.505
A14: SUMIFS | B14: 4)Total Sales for John Smith where quantity is 4
B15: =SUMIFS('cleaned dataset'!I8:I77,'cleaned dataset'!D8:D77,"John Smith",'cleaned dataset'!G8:G77,2) -> 109.98
B17: 5)Find Total Sales where Quantity is > 2 and total > 100
B18: =SUMIFS('cleaned dataset'!I8:I77,'cleaned dataset'!G8:G77,">2",'cleaned dataset'!I8:I77,">100") -> 3563.12
A20: COUNTIF | B20: 6)How many Orders belongs to John Smith
B21: =COUNTIF('cleaned dataset'!D8:D77,"John Smith") -> 1
A23: COUNTIFS | B23: 7)How many Orders were placed by Emily Brown with Quantity 4
B24: =COUNTIFS('cleaned dataset'!D8:D77,"Emily Brown",'cleaned dataset'!G8:G77,4) -> 2
B26: 8)How many Orders have Quantity 3 and Total above 100
B27: =COUNTIFS('cleaned dataset'!G8:G77,3,'cleaned dataset'!I8:I77,">100") -> 15
A29: AND | B29: 9)Is Quantity > 2 AND Total > 100
B30: =AND('cleaned dataset'!G8>2,'cleaned dataset'!I8>100) -> FALSE
A32: AND WITH IF | B32: 10)If Quantity > 2 AND Total > 100 display "High Value" otherwise "Normal"
B33: =IF(AND('cleaned dataset'!G8>2,'cleaned dataset'!I8>100),"High Value","Normal") -> Normal
A35: OR | B35: 11)If Quantity > 3 OR Total > 200
B36: =OR('cleaned dataset'!G10>3,'cleaned dataset'!I10>200) -> TRUE
A38: OR WITH IF | B38: 12)If Quantity > 3 OR Total >200 classify it as an Important Order
B39: =IF(OR('cleaned dataset'!G10>3,'cleaned dataset'!I10>200),"Important Order") -> Important Order
A41: NOT | B41: 13)If Quantity > 2
B42: =NOT('cleaned dataset'!G8) -> FALSE
A44: NOT WITH IF | B44: 14)If Quantity is not > 3 show Normal Quantity
B45: =IF(NOT('cleaned dataset'!G8>3),"Normal Quantity","High Quantity") -> Normal Quantity
A47: IF WITH AND OR | B47: 15)If Quantity > 2 AND Total > 150 OR Tax > 15 "Normal order" otherwise "Normal order"
B48: =IF(AND('cleaned dataset'!G8>2,OR('cleaned dataset'!I8>150,'cleaned dataset'!H8>15)),"Special Order","Normal Order") -> Normal Order
A50: IF WITH AND NESTEDIF | B50: 16)Total > 200 AND Quantity > 2 = Premium,Total > 100 = Regular otherwise Basic
B51: =IF(AND('cleaned dataset'!I8>200,'cleaned dataset'!G8>2),"Premium",IF('cleaned dataset'!I8>100,"Regular","Basic")) -> Regular

Sheet lookup functions
B1: LOOKUP FUNCTIONS
A4: VLOOKUP | B4: To return the Customer Name for Order id 1006
B5: =VLOOKUP('cleaned dataset'!B13,'cleaned dataset'!B8:D77,3,FALSE) -> Lisa Taylor
A7: HLOOKUP | B7: Find Total From Order no. 1001
B8: =HLOOKUP('cleaned dataset'!I8,'cleaned dataset'!B8:I77,2,FALSE) -> 32.989
A10: XLOOKUP | B10: If the Order no. is 1010 find Retail Price
B11: =_xlfn.XLOOKUP(1010,'cleaned dataset'!B8:B78,'cleaned dataset'!F8:F78) -> 199.99
A13: MATCH | B13: Find the position of "Jessica Wilson"
B14: =MATCH("Jessica Wilson",'cleaned dataset'!D8:D77,0) -> 48
A16: INDEX | B16: Find the Total from 15th row
B17: =INDEX('cleaned dataset'!I8:I77,15) -> 87.956
A19: MATCH+INDEX | B19: Find the shipdate for order no.1010
B20: {=INDEX('cleaned dataset'!E8:E77,MATCH('cleaned dataset'!B17,'cleaned dataset'!B8:B77,0))} -> 45299

Sheet KPI
B1: KEY PERFORMANCE INDICATORS
C3: 1)Total Revenue
C4: =SUM('cleaned dataset'!I:I) -> 10855.154
C6: 2)Total No. of Orders
C7: =COUNT('cleaned dataset'!B:B) -> 70
C9: 3)Total Quantity Sold
C10: =SUM('cleaned dataset'!G:G) -> 336
C12: 4)Average Order Value
C13: =AVERAGE('cleaned dataset'!I:I) -> 155.07363
C15: 5)Total Tax Calculated using Named Ranges
C16: =SUM(TAX) -> 986.832
C18: 6)Highest sales
C19: =MAX('cleaned dataset'!I:I) -> 329.967
C21: 7)Lowest Sales
C22: =MIN('cleaned dataset'!I:I) -> 32.989
C24: 8)Average shipping days
C25: =AVERAGE('cleaned dataset'!K8:K77) -> 3.2

Sheet PIVOT TABLE
A2: ORDER QUANTITY WITH TOTAL SALES DONE BY CUSTOMERS
A4: Sum of Total (USD) | B4: Order Quantity
A5: Customer Name | B5: 1 | C5: 2 | D5: 3 | E5: 4 | F5: 5 | G5: Grand Total
A6: Amanda Martinez | B6: 164.989 | G6: 164.989
A7: Amy Hernandez | D7: 164.967 | G7: 164.967
A8: Christopher Rodriguez | B8: 142.989 | G8: 142.989
A9: Christopher Thomas | B9: 98.989 | G9: 98.989
A10: Daniel Brown | C10: 153.978 | E10: 87.956 | G10: 241.934
A11: Daniel Davis | B11: 219.989 | G11: 219.989
A12: Daniel Hernandez | B12: 164.989 | D12: 131.967 | G12: 296.956
A13: Daniel Martinez | D13: 131.967 | G13: 131.967
A14: Daniel Smith | B14: 219.989 | G14: 219.989
A15: Daniel Wilson | F15: 164.945 | G15: 164.945
A16: David Brown | E16: 87.956 | G16: 87.956
A17: David Martinez | C17: 175.978 | G17: 175.978
A18: David Rodriguez | D18: 164.967 | F18: 164.945 | G18: 329.912
A19: David Wilson | B19: 472.967 | G19: 472.967
A20: Emily Brown | C20: 153.978 | E20: 175.912 | G20: 329.89
A21: Emily Davis | B21: 219.989 | G21: 219.989
A22: Emily Johnson | B22: 307.978 | G22: 307.978
A23: Emily Rodriguez | D23: 131.967 | G23: 131.967
A24: James Johnson | C24: 153.978 | G24: 153.978
A25: Jane Doe | B25: 32.989 | G25: 32.989
A26: Jennifer Davis | B26: 219.989 | C26: 153.978 | F26: 164.945 | G26: 538.912
A27: Jennifer Hernandez | B27: 164.989 | D27: 131.967 | G27: 296.956
A28: Jennifer Martinez | C28: 175.978 | G28: 175.978
A29: Jennifer Smith | F29: 164.945 | G29: 164.945
A30: Jessica Gonzalez | B30: 142.989 | G30: 142.989
A31: Jessica Johnson | B31: 142.989 | G31: 142.989
A32: Jessica Martinez | D32: 164.967 | E32: 87.956 | G32: 252.923
A33: Jessica Smith | F33: 164.945 | G33: 164.945
A34: Jessica Wilson | B34: 219.989 | C34: 175.978 | G34: 395.967
A35: John Smith | C35: 109.978 | G35: 109.978
A36: Kimberly Garcia | B36: 219.989 | G36: 219.989
A37: Laura Brown | D37: 131.967 | G37: 131.967
A38: Lisa Taylor | C38: 175.978 | G38: 175.978
A39: Matthew Garcia | B39: 307.978 | G39: 307.978
A40: Matthew Hernandez | C40: 153.978 | G40: 153.978
A41: Matthew Johnson | D41: 131.967 | G41: 131.967
A42: Matthew Smith | D42: 164.967 | E42: 87.956 | G42: 252.923
...

Sheet DASHBOARD
